2019-01-18 22:35:59,976 WARNING base Not Found: /api/action_num/
2019-01-18 22:36:00,001 WARNING base Not Found: /api/visite_num/1/
2019-01-18 22:36:00,018 WARNING base Not Found: /api/base_info/
2019-01-18 22:36:00,035 WARNING base Not Found: /api/edu_info/
2019-01-18 22:36:00,091 WARNING base Not Found: /api/job_info/
2019-01-18 22:36:00,062 WARNING base Not Found: /api/certificate_info/
2019-01-18 22:36:00,118 WARNING base Not Found: /api/pro_info/
2019-01-18 22:36:00,131 WARNING base Not Found: /api/stack_info/
2019-01-18 22:36:03,478 WARNING base Not Found: /api/action_num/
2019-01-18 22:36:03,494 WARNING base Not Found: /api/base_info/
2019-01-18 22:36:03,502 WARNING base Not Found: /api/visite_num/1/
2019-01-18 22:36:03,536 WARNING base Not Found: /api/edu_info/
2019-01-18 22:36:03,563 WARNING base Not Found: /api/certificate_info/
2019-01-18 22:36:03,600 WARNING base Not Found: /api/job_info/
2019-01-18 22:36:03,601 WARNING base Not Found: /api/stack_info/
2019-01-18 22:36:03,612 WARNING base Not Found: /api/pro_info/
2019-01-18 22:36:05,690 WARNING base Not Found: /api/message_info/
2019-01-18 22:36:17,838 WARNING base Not Found: /api/action_num/
2019-01-18 22:36:17,846 WARNING base Not Found: /api/base_info/
2019-01-18 22:36:17,879 WARNING base Not Found: /api/certificate_info/
2019-01-18 22:36:17,890 WARNING base Not Found: /api/visite_num/1/
2019-01-18 22:36:17,893 WARNING base Not Found: /api/edu_info/
2019-01-18 22:36:17,902 WARNING base Not Found: /api/job_info/
2019-01-18 22:36:17,928 WARNING base Not Found: /api/stack_info/
2019-01-18 22:36:17,935 WARNING base Not Found: /api/pro_info/
2019-01-18 22:36:32,436 WARNING base Not Found: /api/action_num/
2019-01-18 22:36:32,454 WARNING base Not Found: /api/visite_num/1/
2019-01-18 22:36:32,476 WARNING base Not Found: /api/certificate_info/
2019-01-18 22:36:32,488 WARNING base Not Found: /api/job_info/
2019-01-18 22:36:32,531 WARNING base Not Found: /api/base_info/
2019-01-18 22:36:32,548 WARNING base Not Found: /api/edu_info/
2019-01-18 22:36:32,578 WARNING base Not Found: /api/stack_info/
2019-01-18 22:36:32,596 WARNING base Not Found: /api/pro_info/
2019-01-18 22:38:52,249 WARNING base Not Found: /api/action_num/
2019-01-18 22:38:52,267 WARNING base Not Found: /api/visite_num/1/
2019-01-18 22:38:52,273 WARNING base Not Found: /api/base_info/
2019-01-18 22:38:52,311 WARNING base Not Found: /api/edu_info/
2019-01-18 22:38:52,362 WARNING base Not Found: /api/pro_info/
2019-01-18 22:38:52,374 WARNING base Not Found: /api/certificate_info/
2019-01-18 22:38:52,392 WARNING base Not Found: /api/job_info/
2019-01-18 22:38:52,419 WARNING base Not Found: /api/stack_info/
2019-01-18 22:38:54,369 WARNING base Not Found: /api/action_num/
2019-01-18 22:38:54,380 WARNING base Not Found: /api/visite_num/1/
2019-01-18 22:38:54,394 WARNING base Not Found: /api/base_info/
2019-01-18 22:38:54,424 WARNING base Not Found: /api/certificate_info/
2019-01-18 22:38:54,435 WARNING base Not Found: /api/edu_info/
2019-01-18 22:38:54,448 WARNING base Not Found: /api/job_info/
2019-01-18 22:38:54,554 WARNING base Not Found: /api/stack_info/
2019-01-18 22:38:54,584 WARNING base Not Found: /api/pro_info/
2019-01-18 22:38:57,864 WARNING base Not Found: /api/action_num/
2019-01-18 22:38:57,879 WARNING base Not Found: /api/visite_num/1/
2019-01-18 22:38:57,911 WARNING base Not Found: /api/edu_info/
2019-01-18 22:38:57,916 WARNING base Not Found: /api/base_info/
2019-01-18 22:38:57,945 WARNING base Not Found: /api/certificate_info/
2019-01-18 22:38:57,994 WARNING base Not Found: /api/job_info/
2019-01-18 22:38:58,012 WARNING base Not Found: /api/pro_info/
2019-01-18 22:38:58,026 WARNING base Not Found: /api/stack_info/
2019-01-18 22:39:21,324 WARNING base Not Found: /api/action_num/
2019-01-18 22:39:21,341 WARNING base Not Found: /api/visite_num/1/
2019-01-18 22:39:21,370 WARNING base Not Found: /api/base_info/
2019-01-18 22:39:21,403 WARNING base Not Found: /api/certificate_info/
2019-01-18 22:39:21,424 WARNING base Not Found: /api/edu_info/
2019-01-18 22:39:21,426 WARNING base Not Found: /api/job_info/
2019-01-18 22:39:21,437 WARNING base Not Found: /api/stack_info/
2019-01-18 22:39:21,453 WARNING base Not Found: /api/pro_info/
2019-01-18 22:39:44,788 WARNING base Not Found: /api/message_info/
2019-01-18 23:01:00,815 ERROR exception Internal Server Error: /ajax_feedback/
Traceback (most recent call last):
  File "D:\Python36\lib\site-packages\django\core\handlers\exception.py", line 35, in inner
    response = get_response(request)
  File "D:\Python36\lib\site-packages\django\core\handlers\base.py", line 128, in _get_response
    response = self.process_exception_by_middleware(e, request)
  File "D:\Python36\lib\site-packages\django\core\handlers\base.py", line 126, in _get_response
    response = wrapped_callback(request, *callback_args, **callback_kwargs)
  File "D:\Python36\lib\site-packages\django\views\decorators\csrf.py", line 54, in wrapped_view
    return view_func(*args, **kwargs)
  File "C:\Users\myx\Desktop\新建文件夹\blog\mysite\views.py", line 138, in ajax_feedback
    fail_silently=False
  File "D:\Python36\lib\site-packages\django\core\mail\__init__.py", line 60, in send_mail
    return mail.send()
  File "D:\Python36\lib\site-packages\django\core\mail\message.py", line 294, in send
    return self.get_connection(fail_silently).send_messages([self])
  File "D:\Python36\lib\site-packages\django\core\mail\backends\smtp.py", line 103, in send_messages
    new_conn_created = self.open()
  File "D:\Python36\lib\site-packages\django\core\mail\backends\smtp.py", line 63, in open
    self.connection = self.connection_class(self.host, self.port, **connection_params)
  File "D:\Python36\lib\smtplib.py", line 251, in __init__
    (code, msg) = self.connect(host, port)
  File "D:\Python36\lib\smtplib.py", line 337, in connect
    (code, msg) = self.getreply()
  File "D:\Python36\lib\smtplib.py", line 393, in getreply
    raise SMTPServerDisconnected("Connection unexpectedly closed")
smtplib.SMTPServerDisconnected: Connection unexpectedly closed
2019-01-18 23:01:05,969 ERROR exception Internal Server Error: /ajax_feedback/
Traceback (most recent call last):
  File "D:\Python36\lib\site-packages\django\core\handlers\exception.py", line 35, in inner
    response = get_response(request)
  File "D:\Python36\lib\site-packages\django\core\handlers\base.py", line 128, in _get_response
    response = self.process_exception_by_middleware(e, request)
  File "D:\Python36\lib\site-packages\django\core\handlers\base.py", line 126, in _get_response
    response = wrapped_callback(request, *callback_args, **callback_kwargs)
  File "D:\Python36\lib\site-packages\django\views\decorators\csrf.py", line 54, in wrapped_view
    return view_func(*args, **kwargs)
  File "C:\Users\myx\Desktop\新建文件夹\blog\mysite\views.py", line 138, in ajax_feedback
    fail_silently=False
  File "D:\Python36\lib\site-packages\django\core\mail\__init__.py", line 60, in send_mail
    return mail.send()
  File "D:\Python36\lib\site-packages\django\core\mail\message.py", line 294, in send
    return self.get_connection(fail_silently).send_messages([self])
  File "D:\Python36\lib\site-packages\django\core\mail\backends\smtp.py", line 103, in send_messages
    new_conn_created = self.open()
  File "D:\Python36\lib\site-packages\django\core\mail\backends\smtp.py", line 63, in open
    self.connection = self.connection_class(self.host, self.port, **connection_params)
  File "D:\Python36\lib\smtplib.py", line 251, in __init__
    (code, msg) = self.connect(host, port)
  File "D:\Python36\lib\smtplib.py", line 337, in connect
    (code, msg) = self.getreply()
  File "D:\Python36\lib\smtplib.py", line 393, in getreply
    raise SMTPServerDisconnected("Connection unexpectedly closed")
smtplib.SMTPServerDisconnected: Connection unexpectedly closed
2019-01-18 23:01:09,568 ERROR exception Internal Server Error: /ajax_feedback/
Traceback (most recent call last):
  File "D:\Python36\lib\site-packages\django\core\handlers\exception.py", line 35, in inner
    response = get_response(request)
  File "D:\Python36\lib\site-packages\django\core\handlers\base.py", line 128, in _get_response
    response = self.process_exception_by_middleware(e, request)
  File "D:\Python36\lib\site-packages\django\core\handlers\base.py", line 126, in _get_response
    response = wrapped_callback(request, *callback_args, **callback_kwargs)
  File "D:\Python36\lib\site-packages\django\views\decorators\csrf.py", line 54, in wrapped_view
    return view_func(*args, **kwargs)
  File "C:\Users\myx\Desktop\新建文件夹\blog\mysite\views.py", line 138, in ajax_feedback
    fail_silently=False
  File "D:\Python36\lib\site-packages\django\core\mail\__init__.py", line 60, in send_mail
    return mail.send()
  File "D:\Python36\lib\site-packages\django\core\mail\message.py", line 294, in send
    return self.get_connection(fail_silently).send_messages([self])
  File "D:\Python36\lib\site-packages\django\core\mail\backends\smtp.py", line 103, in send_messages
    new_conn_created = self.open()
  File "D:\Python36\lib\site-packages\django\core\mail\backends\smtp.py", line 63, in open
    self.connection = self.connection_class(self.host, self.port, **connection_params)
  File "D:\Python36\lib\smtplib.py", line 251, in __init__
    (code, msg) = self.connect(host, port)
  File "D:\Python36\lib\smtplib.py", line 337, in connect
    (code, msg) = self.getreply()
  File "D:\Python36\lib\smtplib.py", line 393, in getreply
    raise SMTPServerDisconnected("Connection unexpectedly closed")
smtplib.SMTPServerDisconnected: Connection unexpectedly closed
2019-01-18 23:01:10,764 ERROR exception Internal Server Error: /ajax_feedback/
Traceback (most recent call last):
  File "D:\Python36\lib\site-packages\django\core\handlers\exception.py", line 35, in inner
    response = get_response(request)
  File "D:\Python36\lib\site-packages\django\core\handlers\base.py", line 128, in _get_response
    response = self.process_exception_by_middleware(e, request)
  File "D:\Python36\lib\site-packages\django\core\handlers\base.py", line 126, in _get_response
    response = wrapped_callback(request, *callback_args, **callback_kwargs)
  File "D:\Python36\lib\site-packages\django\views\decorators\csrf.py", line 54, in wrapped_view
    return view_func(*args, **kwargs)
  File "C:\Users\myx\Desktop\新建文件夹\blog\mysite\views.py", line 138, in ajax_feedback
    fail_silently=False
  File "D:\Python36\lib\site-packages\django\core\mail\__init__.py", line 60, in send_mail
    return mail.send()
  File "D:\Python36\lib\site-packages\django\core\mail\message.py", line 294, in send
    return self.get_connection(fail_silently).send_messages([self])
  File "D:\Python36\lib\site-packages\django\core\mail\backends\smtp.py", line 103, in send_messages
    new_conn_created = self.open()
  File "D:\Python36\lib\site-packages\django\core\mail\backends\smtp.py", line 63, in open
    self.connection = self.connection_class(self.host, self.port, **connection_params)
  File "D:\Python36\lib\smtplib.py", line 251, in __init__
    (code, msg) = self.connect(host, port)
  File "D:\Python36\lib\smtplib.py", line 337, in connect
    (code, msg) = self.getreply()
  File "D:\Python36\lib\smtplib.py", line 393, in getreply
    raise SMTPServerDisconnected("Connection unexpectedly closed")
smtplib.SMTPServerDisconnected: Connection unexpectedly closed
2019-01-18 23:01:11,081 ERROR exception Internal Server Error: /ajax_feedback/
Traceback (most recent call last):
  File "D:\Python36\lib\site-packages\django\core\handlers\exception.py", line 35, in inner
    response = get_response(request)
  File "D:\Python36\lib\site-packages\django\core\handlers\base.py", line 128, in _get_response
    response = self.process_exception_by_middleware(e, request)
  File "D:\Python36\lib\site-packages\django\core\handlers\base.py", line 126, in _get_response
    response = wrapped_callback(request, *callback_args, **callback_kwargs)
  File "D:\Python36\lib\site-packages\django\views\decorators\csrf.py", line 54, in wrapped_view
    return view_func(*args, **kwargs)
  File "C:\Users\myx\Desktop\新建文件夹\blog\mysite\views.py", line 138, in ajax_feedback
    fail_silently=False
  File "D:\Python36\lib\site-packages\django\core\mail\__init__.py", line 60, in send_mail
    return mail.send()
  File "D:\Python36\lib\site-packages\django\core\mail\message.py", line 294, in send
    return self.get_connection(fail_silently).send_messages([self])
  File "D:\Python36\lib\site-packages\django\core\mail\backends\smtp.py", line 103, in send_messages
    new_conn_created = self.open()
  File "D:\Python36\lib\site-packages\django\core\mail\backends\smtp.py", line 63, in open
    self.connection = self.connection_class(self.host, self.port, **connection_params)
  File "D:\Python36\lib\smtplib.py", line 251, in __init__
    (code, msg) = self.connect(host, port)
  File "D:\Python36\lib\smtplib.py", line 337, in connect
    (code, msg) = self.getreply()
  File "D:\Python36\lib\smtplib.py", line 393, in getreply
    raise SMTPServerDisconnected("Connection unexpectedly closed")
smtplib.SMTPServerDisconnected: Connection unexpectedly closed
2019-01-18 23:01:12,711 ERROR exception Internal Server Error: /ajax_feedback/
Traceback (most recent call last):
  File "D:\Python36\lib\site-packages\django\core\handlers\exception.py", line 35, in inner
    response = get_response(request)
  File "D:\Python36\lib\site-packages\django\core\handlers\base.py", line 128, in _get_response
    response = self.process_exception_by_middleware(e, request)
  File "D:\Python36\lib\site-packages\django\core\handlers\base.py", line 126, in _get_response
    response = wrapped_callback(request, *callback_args, **callback_kwargs)
  File "D:\Python36\lib\site-packages\django\views\decorators\csrf.py", line 54, in wrapped_view
    return view_func(*args, **kwargs)
  File "C:\Users\myx\Desktop\新建文件夹\blog\mysite\views.py", line 138, in ajax_feedback
    fail_silently=False
  File "D:\Python36\lib\site-packages\django\core\mail\__init__.py", line 60, in send_mail
    return mail.send()
  File "D:\Python36\lib\site-packages\django\core\mail\message.py", line 294, in send
    return self.get_connection(fail_silently).send_messages([self])
  File "D:\Python36\lib\site-packages\django\core\mail\backends\smtp.py", line 103, in send_messages
    new_conn_created = self.open()
  File "D:\Python36\lib\site-packages\django\core\mail\backends\smtp.py", line 63, in open
    self.connection = self.connection_class(self.host, self.port, **connection_params)
  File "D:\Python36\lib\smtplib.py", line 251, in __init__
    (code, msg) = self.connect(host, port)
  File "D:\Python36\lib\smtplib.py", line 337, in connect
    (code, msg) = self.getreply()
  File "D:\Python36\lib\smtplib.py", line 393, in getreply
    raise SMTPServerDisconnected("Connection unexpectedly closed")
smtplib.SMTPServerDisconnected: Connection unexpectedly closed
2019-01-18 23:01:19,377 ERROR exception Internal Server Error: /ajax_feedback/
Traceback (most recent call last):
  File "D:\Python36\lib\site-packages\django\core\handlers\exception.py", line 35, in inner
    response = get_response(request)
  File "D:\Python36\lib\site-packages\django\core\handlers\base.py", line 128, in _get_response
    response = self.process_exception_by_middleware(e, request)
  File "D:\Python36\lib\site-packages\django\core\handlers\base.py", line 126, in _get_response
    response = wrapped_callback(request, *callback_args, **callback_kwargs)
  File "D:\Python36\lib\site-packages\django\views\decorators\csrf.py", line 54, in wrapped_view
    return view_func(*args, **kwargs)
  File "C:\Users\myx\Desktop\新建文件夹\blog\mysite\views.py", line 138, in ajax_feedback
    fail_silently=False
  File "D:\Python36\lib\site-packages\django\core\mail\__init__.py", line 60, in send_mail
    return mail.send()
  File "D:\Python36\lib\site-packages\django\core\mail\message.py", line 294, in send
    return self.get_connection(fail_silently).send_messages([self])
  File "D:\Python36\lib\site-packages\django\core\mail\backends\smtp.py", line 103, in send_messages
    new_conn_created = self.open()
  File "D:\Python36\lib\site-packages\django\core\mail\backends\smtp.py", line 63, in open
    self.connection = self.connection_class(self.host, self.port, **connection_params)
  File "D:\Python36\lib\smtplib.py", line 251, in __init__
    (code, msg) = self.connect(host, port)
  File "D:\Python36\lib\smtplib.py", line 337, in connect
    (code, msg) = self.getreply()
  File "D:\Python36\lib\smtplib.py", line 393, in getreply
    raise SMTPServerDisconnected("Connection unexpectedly closed")
smtplib.SMTPServerDisconnected: Connection unexpectedly closed
2019-01-18 23:01:25,687 ERROR exception Internal Server Error: /ajax_feedback/
Traceback (most recent call last):
  File "D:\Python36\lib\site-packages\django\core\handlers\exception.py", line 35, in inner
    response = get_response(request)
  File "D:\Python36\lib\site-packages\django\core\handlers\base.py", line 128, in _get_response
    response = self.process_exception_by_middleware(e, request)
  File "D:\Python36\lib\site-packages\django\core\handlers\base.py", line 126, in _get_response
    response = wrapped_callback(request, *callback_args, **callback_kwargs)
  File "D:\Python36\lib\site-packages\django\views\decorators\csrf.py", line 54, in wrapped_view
    return view_func(*args, **kwargs)
  File "C:\Users\myx\Desktop\新建文件夹\blog\mysite\views.py", line 138, in ajax_feedback
    fail_silently=False
  File "D:\Python36\lib\site-packages\django\core\mail\__init__.py", line 60, in send_mail
    return mail.send()
  File "D:\Python36\lib\site-packages\django\core\mail\message.py", line 294, in send
    return self.get_connection(fail_silently).send_messages([self])
  File "D:\Python36\lib\site-packages\django\core\mail\backends\smtp.py", line 103, in send_messages
    new_conn_created = self.open()
  File "D:\Python36\lib\site-packages\django\core\mail\backends\smtp.py", line 63, in open
    self.connection = self.connection_class(self.host, self.port, **connection_params)
  File "D:\Python36\lib\smtplib.py", line 251, in __init__
    (code, msg) = self.connect(host, port)
  File "D:\Python36\lib\smtplib.py", line 337, in connect
    (code, msg) = self.getreply()
  File "D:\Python36\lib\smtplib.py", line 393, in getreply
    raise SMTPServerDisconnected("Connection unexpectedly closed")
smtplib.SMTPServerDisconnected: Connection unexpectedly closed
2019-01-18 23:01:27,117 ERROR exception Internal Server Error: /ajax_feedback/
Traceback (most recent call last):
  File "D:\Python36\lib\site-packages\django\core\handlers\exception.py", line 35, in inner
    response = get_response(request)
  File "D:\Python36\lib\site-packages\django\core\handlers\base.py", line 128, in _get_response
    response = self.process_exception_by_middleware(e, request)
  File "D:\Python36\lib\site-packages\django\core\handlers\base.py", line 126, in _get_response
    response = wrapped_callback(request, *callback_args, **callback_kwargs)
  File "D:\Python36\lib\site-packages\django\views\decorators\csrf.py", line 54, in wrapped_view
    return view_func(*args, **kwargs)
  File "C:\Users\myx\Desktop\新建文件夹\blog\mysite\views.py", line 138, in ajax_feedback
    fail_silently=False
  File "D:\Python36\lib\site-packages\django\core\mail\__init__.py", line 60, in send_mail
    return mail.send()
  File "D:\Python36\lib\site-packages\django\core\mail\message.py", line 294, in send
    return self.get_connection(fail_silently).send_messages([self])
  File "D:\Python36\lib\site-packages\django\core\mail\backends\smtp.py", line 103, in send_messages
    new_conn_created = self.open()
  File "D:\Python36\lib\site-packages\django\core\mail\backends\smtp.py", line 63, in open
    self.connection = self.connection_class(self.host, self.port, **connection_params)
  File "D:\Python36\lib\smtplib.py", line 251, in __init__
    (code, msg) = self.connect(host, port)
  File "D:\Python36\lib\smtplib.py", line 337, in connect
    (code, msg) = self.getreply()
  File "D:\Python36\lib\smtplib.py", line 393, in getreply
    raise SMTPServerDisconnected("Connection unexpectedly closed")
smtplib.SMTPServerDisconnected: Connection unexpectedly closed
2019-01-18 23:01:27,340 ERROR exception Internal Server Error: /ajax_feedback/
Traceback (most recent call last):
  File "D:\Python36\lib\site-packages\django\core\handlers\exception.py", line 35, in inner
    response = get_response(request)
  File "D:\Python36\lib\site-packages\django\core\handlers\base.py", line 128, in _get_response
    response = self.process_exception_by_middleware(e, request)
  File "D:\Python36\lib\site-packages\django\core\handlers\base.py", line 126, in _get_response
    response = wrapped_callback(request, *callback_args, **callback_kwargs)
  File "D:\Python36\lib\site-packages\django\views\decorators\csrf.py", line 54, in wrapped_view
    return view_func(*args, **kwargs)
  File "C:\Users\myx\Desktop\新建文件夹\blog\mysite\views.py", line 138, in ajax_feedback
    fail_silently=False
  File "D:\Python36\lib\site-packages\django\core\mail\__init__.py", line 60, in send_mail
    return mail.send()
  File "D:\Python36\lib\site-packages\django\core\mail\message.py", line 294, in send
    return self.get_connection(fail_silently).send_messages([self])
  File "D:\Python36\lib\site-packages\django\core\mail\backends\smtp.py", line 103, in send_messages
    new_conn_created = self.open()
  File "D:\Python36\lib\site-packages\django\core\mail\backends\smtp.py", line 63, in open
    self.connection = self.connection_class(self.host, self.port, **connection_params)
  File "D:\Python36\lib\smtplib.py", line 251, in __init__
    (code, msg) = self.connect(host, port)
  File "D:\Python36\lib\smtplib.py", line 337, in connect
    (code, msg) = self.getreply()
  File "D:\Python36\lib\smtplib.py", line 393, in getreply
    raise SMTPServerDisconnected("Connection unexpectedly closed")
smtplib.SMTPServerDisconnected: Connection unexpectedly closed
2019-01-18 23:01:28,715 ERROR exception Internal Server Error: /ajax_feedback/
Traceback (most recent call last):
  File "D:\Python36\lib\site-packages\django\core\handlers\exception.py", line 35, in inner
    response = get_response(request)
  File "D:\Python36\lib\site-packages\django\core\handlers\base.py", line 128, in _get_response
    response = self.process_exception_by_middleware(e, request)
  File "D:\Python36\lib\site-packages\django\core\handlers\base.py", line 126, in _get_response
    response = wrapped_callback(request, *callback_args, **callback_kwargs)
  File "D:\Python36\lib\site-packages\django\views\decorators\csrf.py", line 54, in wrapped_view
    return view_func(*args, **kwargs)
  File "C:\Users\myx\Desktop\新建文件夹\blog\mysite\views.py", line 138, in ajax_feedback
    fail_silently=False
  File "D:\Python36\lib\site-packages\django\core\mail\__init__.py", line 60, in send_mail
    return mail.send()
  File "D:\Python36\lib\site-packages\django\core\mail\message.py", line 294, in send
    return self.get_connection(fail_silently).send_messages([self])
  File "D:\Python36\lib\site-packages\django\core\mail\backends\smtp.py", line 103, in send_messages
    new_conn_created = self.open()
  File "D:\Python36\lib\site-packages\django\core\mail\backends\smtp.py", line 63, in open
    self.connection = self.connection_class(self.host, self.port, **connection_params)
  File "D:\Python36\lib\smtplib.py", line 251, in __init__
    (code, msg) = self.connect(host, port)
  File "D:\Python36\lib\smtplib.py", line 337, in connect
    (code, msg) = self.getreply()
  File "D:\Python36\lib\smtplib.py", line 393, in getreply
    raise SMTPServerDisconnected("Connection unexpectedly closed")
smtplib.SMTPServerDisconnected: Connection unexpectedly closed
2019-01-18 23:01:29,233 ERROR exception Internal Server Error: /ajax_feedback/
Traceback (most recent call last):
  File "D:\Python36\lib\site-packages\django\core\handlers\exception.py", line 35, in inner
    response = get_response(request)
  File "D:\Python36\lib\site-packages\django\core\handlers\base.py", line 128, in _get_response
    response = self.process_exception_by_middleware(e, request)
  File "D:\Python36\lib\site-packages\django\core\handlers\base.py", line 126, in _get_response
    response = wrapped_callback(request, *callback_args, **callback_kwargs)
  File "D:\Python36\lib\site-packages\django\views\decorators\csrf.py", line 54, in wrapped_view
    return view_func(*args, **kwargs)
  File "C:\Users\myx\Desktop\新建文件夹\blog\mysite\views.py", line 138, in ajax_feedback
    fail_silently=False
  File "D:\Python36\lib\site-packages\django\core\mail\__init__.py", line 60, in send_mail
    return mail.send()
  File "D:\Python36\lib\site-packages\django\core\mail\message.py", line 294, in send
    return self.get_connection(fail_silently).send_messages([self])
  File "D:\Python36\lib\site-packages\django\core\mail\backends\smtp.py", line 103, in send_messages
    new_conn_created = self.open()
  File "D:\Python36\lib\site-packages\django\core\mail\backends\smtp.py", line 63, in open
    self.connection = self.connection_class(self.host, self.port, **connection_params)
  File "D:\Python36\lib\smtplib.py", line 251, in __init__
    (code, msg) = self.connect(host, port)
  File "D:\Python36\lib\smtplib.py", line 337, in connect
    (code, msg) = self.getreply()
  File "D:\Python36\lib\smtplib.py", line 393, in getreply
    raise SMTPServerDisconnected("Connection unexpectedly closed")
smtplib.SMTPServerDisconnected: Connection unexpectedly closed
2019-01-18 23:01:37,823 ERROR exception Internal Server Error: /ajax_feedback/
Traceback (most recent call last):
  File "D:\Python36\lib\site-packages\django\core\handlers\exception.py", line 35, in inner
    response = get_response(request)
  File "D:\Python36\lib\site-packages\django\core\handlers\base.py", line 128, in _get_response
    response = self.process_exception_by_middleware(e, request)
  File "D:\Python36\lib\site-packages\django\core\handlers\base.py", line 126, in _get_response
    response = wrapped_callback(request, *callback_args, **callback_kwargs)
  File "D:\Python36\lib\site-packages\django\views\decorators\csrf.py", line 54, in wrapped_view
    return view_func(*args, **kwargs)
  File "C:\Users\myx\Desktop\新建文件夹\blog\mysite\views.py", line 138, in ajax_feedback
    fail_silently=False
  File "D:\Python36\lib\site-packages\django\core\mail\__init__.py", line 60, in send_mail
    return mail.send()
  File "D:\Python36\lib\site-packages\django\core\mail\message.py", line 294, in send
    return self.get_connection(fail_silently).send_messages([self])
  File "D:\Python36\lib\site-packages\django\core\mail\backends\smtp.py", line 103, in send_messages
    new_conn_created = self.open()
  File "D:\Python36\lib\site-packages\django\core\mail\backends\smtp.py", line 63, in open
    self.connection = self.connection_class(self.host, self.port, **connection_params)
  File "D:\Python36\lib\smtplib.py", line 251, in __init__
    (code, msg) = self.connect(host, port)
  File "D:\Python36\lib\smtplib.py", line 337, in connect
    (code, msg) = self.getreply()
  File "D:\Python36\lib\smtplib.py", line 393, in getreply
    raise SMTPServerDisconnected("Connection unexpectedly closed")
smtplib.SMTPServerDisconnected: Connection unexpectedly closed
2019-01-18 23:01:42,642 ERROR exception Internal Server Error: /ajax_feedback/
Traceback (most recent call last):
  File "D:\Python36\lib\site-packages\django\core\handlers\exception.py", line 35, in inner
    response = get_response(request)
  File "D:\Python36\lib\site-packages\django\core\handlers\base.py", line 128, in _get_response
    response = self.process_exception_by_middleware(e, request)
  File "D:\Python36\lib\site-packages\django\core\handlers\base.py", line 126, in _get_response
    response = wrapped_callback(request, *callback_args, **callback_kwargs)
  File "D:\Python36\lib\site-packages\django\views\decorators\csrf.py", line 54, in wrapped_view
    return view_func(*args, **kwargs)
  File "C:\Users\myx\Desktop\新建文件夹\blog\mysite\views.py", line 138, in ajax_feedback
    fail_silently=False
  File "D:\Python36\lib\site-packages\django\core\mail\__init__.py", line 60, in send_mail
    return mail.send()
  File "D:\Python36\lib\site-packages\django\core\mail\message.py", line 294, in send
    return self.get_connection(fail_silently).send_messages([self])
  File "D:\Python36\lib\site-packages\django\core\mail\backends\smtp.py", line 103, in send_messages
    new_conn_created = self.open()
  File "D:\Python36\lib\site-packages\django\core\mail\backends\smtp.py", line 63, in open
    self.connection = self.connection_class(self.host, self.port, **connection_params)
  File "D:\Python36\lib\smtplib.py", line 251, in __init__
    (code, msg) = self.connect(host, port)
  File "D:\Python36\lib\smtplib.py", line 337, in connect
    (code, msg) = self.getreply()
  File "D:\Python36\lib\smtplib.py", line 393, in getreply
    raise SMTPServerDisconnected("Connection unexpectedly closed")
smtplib.SMTPServerDisconnected: Connection unexpectedly closed
2019-01-18 23:01:44,837 ERROR exception Internal Server Error: /ajax_feedback/
Traceback (most recent call last):
  File "D:\Python36\lib\site-packages\django\core\handlers\exception.py", line 35, in inner
    response = get_response(request)
  File "D:\Python36\lib\site-packages\django\core\handlers\base.py", line 128, in _get_response
    response = self.process_exception_by_middleware(e, request)
  File "D:\Python36\lib\site-packages\django\core\handlers\base.py", line 126, in _get_response
    response = wrapped_callback(request, *callback_args, **callback_kwargs)
  File "D:\Python36\lib\site-packages\django\views\decorators\csrf.py", line 54, in wrapped_view
    return view_func(*args, **kwargs)
  File "C:\Users\myx\Desktop\新建文件夹\blog\mysite\views.py", line 138, in ajax_feedback
    fail_silently=False
  File "D:\Python36\lib\site-packages\django\core\mail\__init__.py", line 60, in send_mail
    return mail.send()
  File "D:\Python36\lib\site-packages\django\core\mail\message.py", line 294, in send
    return self.get_connection(fail_silently).send_messages([self])
  File "D:\Python36\lib\site-packages\django\core\mail\backends\smtp.py", line 103, in send_messages
    new_conn_created = self.open()
  File "D:\Python36\lib\site-packages\django\core\mail\backends\smtp.py", line 63, in open
    self.connection = self.connection_class(self.host, self.port, **connection_params)
  File "D:\Python36\lib\smtplib.py", line 251, in __init__
    (code, msg) = self.connect(host, port)
  File "D:\Python36\lib\smtplib.py", line 337, in connect
    (code, msg) = self.getreply()
  File "D:\Python36\lib\smtplib.py", line 393, in getreply
    raise SMTPServerDisconnected("Connection unexpectedly closed")
smtplib.SMTPServerDisconnected: Connection unexpectedly closed
2019-01-18 23:01:45,816 ERROR exception Internal Server Error: /ajax_feedback/
Traceback (most recent call last):
  File "D:\Python36\lib\site-packages\django\core\handlers\exception.py", line 35, in inner
    response = get_response(request)
  File "D:\Python36\lib\site-packages\django\core\handlers\base.py", line 128, in _get_response
    response = self.process_exception_by_middleware(e, request)
  File "D:\Python36\lib\site-packages\django\core\handlers\base.py", line 126, in _get_response
    response = wrapped_callback(request, *callback_args, **callback_kwargs)
  File "D:\Python36\lib\site-packages\django\views\decorators\csrf.py", line 54, in wrapped_view
    return view_func(*args, **kwargs)
  File "C:\Users\myx\Desktop\新建文件夹\blog\mysite\views.py", line 138, in ajax_feedback
    fail_silently=False
  File "D:\Python36\lib\site-packages\django\core\mail\__init__.py", line 60, in send_mail
    return mail.send()
  File "D:\Python36\lib\site-packages\django\core\mail\message.py", line 294, in send
    return self.get_connection(fail_silently).send_messages([self])
  File "D:\Python36\lib\site-packages\django\core\mail\backends\smtp.py", line 103, in send_messages
    new_conn_created = self.open()
  File "D:\Python36\lib\site-packages\django\core\mail\backends\smtp.py", line 63, in open
    self.connection = self.connection_class(self.host, self.port, **connection_params)
  File "D:\Python36\lib\smtplib.py", line 251, in __init__
    (code, msg) = self.connect(host, port)
  File "D:\Python36\lib\smtplib.py", line 337, in connect
    (code, msg) = self.getreply()
  File "D:\Python36\lib\smtplib.py", line 393, in getreply
    raise SMTPServerDisconnected("Connection unexpectedly closed")
smtplib.SMTPServerDisconnected: Connection unexpectedly closed
2019-01-18 23:01:46,144 ERROR exception Internal Server Error: /ajax_feedback/
Traceback (most recent call last):
  File "D:\Python36\lib\site-packages\django\core\handlers\exception.py", line 35, in inner
    response = get_response(request)
  File "D:\Python36\lib\site-packages\django\core\handlers\base.py", line 128, in _get_response
    response = self.process_exception_by_middleware(e, request)
  File "D:\Python36\lib\site-packages\django\core\handlers\base.py", line 126, in _get_response
    response = wrapped_callback(request, *callback_args, **callback_kwargs)
  File "D:\Python36\lib\site-packages\django\views\decorators\csrf.py", line 54, in wrapped_view
    return view_func(*args, **kwargs)
  File "C:\Users\myx\Desktop\新建文件夹\blog\mysite\views.py", line 138, in ajax_feedback
    fail_silently=False
  File "D:\Python36\lib\site-packages\django\core\mail\__init__.py", line 60, in send_mail
    return mail.send()
  File "D:\Python36\lib\site-packages\django\core\mail\message.py", line 294, in send
    return self.get_connection(fail_silently).send_messages([self])
  File "D:\Python36\lib\site-packages\django\core\mail\backends\smtp.py", line 103, in send_messages
    new_conn_created = self.open()
  File "D:\Python36\lib\site-packages\django\core\mail\backends\smtp.py", line 63, in open
    self.connection = self.connection_class(self.host, self.port, **connection_params)
  File "D:\Python36\lib\smtplib.py", line 251, in __init__
    (code, msg) = self.connect(host, port)
  File "D:\Python36\lib\smtplib.py", line 337, in connect
    (code, msg) = self.getreply()
  File "D:\Python36\lib\smtplib.py", line 393, in getreply
    raise SMTPServerDisconnected("Connection unexpectedly closed")
smtplib.SMTPServerDisconnected: Connection unexpectedly closed
2019-01-18 23:01:57,979 ERROR exception Internal Server Error: /ajax_feedback/
Traceback (most recent call last):
  File "D:\Python36\lib\site-packages\django\core\handlers\exception.py", line 35, in inner
    response = get_response(request)
  File "D:\Python36\lib\site-packages\django\core\handlers\base.py", line 128, in _get_response
    response = self.process_exception_by_middleware(e, request)
  File "D:\Python36\lib\site-packages\django\core\handlers\base.py", line 126, in _get_response
    response = wrapped_callback(request, *callback_args, **callback_kwargs)
  File "D:\Python36\lib\site-packages\django\views\decorators\csrf.py", line 54, in wrapped_view
    return view_func(*args, **kwargs)
  File "C:\Users\myx\Desktop\新建文件夹\blog\mysite\views.py", line 138, in ajax_feedback
    fail_silently=False
  File "D:\Python36\lib\site-packages\django\core\mail\__init__.py", line 60, in send_mail
    return mail.send()
  File "D:\Python36\lib\site-packages\django\core\mail\message.py", line 294, in send
    return self.get_connection(fail_silently).send_messages([self])
  File "D:\Python36\lib\site-packages\django\core\mail\backends\smtp.py", line 103, in send_messages
    new_conn_created = self.open()
  File "D:\Python36\lib\site-packages\django\core\mail\backends\smtp.py", line 63, in open
    self.connection = self.connection_class(self.host, self.port, **connection_params)
  File "D:\Python36\lib\smtplib.py", line 251, in __init__
    (code, msg) = self.connect(host, port)
  File "D:\Python36\lib\smtplib.py", line 337, in connect
    (code, msg) = self.getreply()
  File "D:\Python36\lib\smtplib.py", line 393, in getreply
    raise SMTPServerDisconnected("Connection unexpectedly closed")
smtplib.SMTPServerDisconnected: Connection unexpectedly closed
2019-01-18 23:02:55,473 WARNING base Not Found: /favicon.ico
2019-01-19 00:24:02,959 ERROR exception Internal Server Error: /news-index/17/
Traceback (most recent call last):
  File "D:\Python36\lib\site-packages\django\core\handlers\exception.py", line 35, in inner
    response = get_response(request)
  File "D:\Python36\lib\site-packages\django\core\handlers\base.py", line 128, in _get_response
    response = self.process_exception_by_middleware(e, request)
  File "D:\Python36\lib\site-packages\django\core\handlers\base.py", line 126, in _get_response
    response = wrapped_callback(request, *callback_args, **callback_kwargs)
  File "C:\Users\myx\Desktop\新建文件夹\blog\mysite\views.py", line 51, in news_detail
    author = Reg_user.objects.get(username=session_username)
NameError: name 'session_username' is not defined
2019-01-19 00:24:03,693 WARNING base Not Found: /favicon.ico
2019-01-19 00:24:39,478 ERROR exception Internal Server Error: /news-index/18/
Traceback (most recent call last):
  File "D:\Python36\lib\site-packages\django\core\handlers\exception.py", line 35, in inner
    response = get_response(request)
  File "D:\Python36\lib\site-packages\django\core\handlers\base.py", line 128, in _get_response
    response = self.process_exception_by_middleware(e, request)
  File "D:\Python36\lib\site-packages\django\core\handlers\base.py", line 126, in _get_response
    response = wrapped_callback(request, *callback_args, **callback_kwargs)
  File "C:\Users\myx\Desktop\新建文件夹\blog\mysite\views.py", line 51, in news_detail
    author = Reg_user.objects.get(username=session_username)
NameError: name 'session_username' is not defined
2019-01-19 00:25:46,077 ERROR exception Internal Server Error: /blog-index/26/
Traceback (most recent call last):
  File "D:\Python36\lib\site-packages\django\core\handlers\exception.py", line 35, in inner
    response = get_response(request)
  File "D:\Python36\lib\site-packages\django\core\handlers\base.py", line 128, in _get_response
    response = self.process_exception_by_middleware(e, request)
  File "D:\Python36\lib\site-packages\django\core\handlers\base.py", line 126, in _get_response
    response = wrapped_callback(request, *callback_args, **callback_kwargs)
  File "C:\Users\myx\Desktop\新建文件夹\blog\mysite\views.py", line 79, in blog_detail
    author = Reg_user.objects.get(username=session_username)
NameError: name 'session_username' is not defined
